<?xml version="1.0"?>
<robot xmlns:xacro="http://www.ros.org/wiki/xacro" name="gazebo_traffic_light">

  <!-- Define some properties for reusability -->
  <xacro:property name="box_size" value="0.1 0.6 1.2"/>
  <xacro:property name="cylinder_radius" value="0.15"/>
  <xacro:property name="green_off_length" value="0.05"/>
  <xacro:property name="green_on_length" value="0.002"/>
  <xacro:property name="yellow_off_length" value="0.05"/>
  <xacro:property name="yellow_on_length" value="0.002"/>
  <xacro:property name="red_off_length" value="0.05"/>
  <xacro:property name="red_on_length" value="0.002"/>

  <!-- Cantilevered Light Model -->
  <link name="base">
    <inertial>
      <mass value="1.0"/>
      <origin xyz="0 0 0" rpy="0 0 0"/>
      <inertia ixx="1.0" ixy="0.0" ixz="0.0" iyy="1.0" iyz="0.0" izz="1.0"/>
    </inertial>
    <visual>
      <geometry>
        <cylinder radius="0.25" length="6.55"/>
      </geometry>
      <origin xyz="0 0 3.275" rpy="0 0 0"/>
      <material name="black"/>
    </visual>
    <collision>
      <geometry>
        <cylinder radius="0.25" length="6.55"/>
      </geometry>
      <origin xyz="0 0 3.275" rpy="0 0 0"/>
    </collision>
  </link>

  <gazebo reference="base">
    <gravity>0</gravity>
  </gazebo>

  <link name="cross_beam">
    <inertial>
      <mass value="1.0"/>
      <origin xyz="0 0 0" rpy="0 0 0"/>
      <inertia ixx="1.0" ixy="0.0" ixz="0.0" iyy="1.0" iyz="0.0" izz="1.0"/>
    </inertial>
    <visual>
      <geometry>
        <cylinder radius="0.125" length="6.0"/>
      </geometry>
      <origin xyz="0 0 3.0" rpy="0 0 0"/>
      <material name="black"/>
    </visual>
    <collision>
      <geometry>
        <cylinder radius="0.125" length="6.0"/>
      </geometry>
      <origin xyz="0 0 3.0" rpy="0 0 0"/>
    </collision>
  </link>

  <gazebo reference="cross_beam">
    <gravity>0</gravity>
  </gazebo>

  <joint name="cross_beam_fixed" type="fixed">
    <parent link="base"/>
    <child link="cross_beam"/>
    <origin xyz="0 0 6.015" rpy="1.5707 0 0"/>
  </joint>

  <!-- Traffic Light Model 1 -->
  <link name="light_fixture_1">
    <visual>
      <geometry>
        <box size="${box_size}" />
      </geometry>
      <origin xyz="0 0 0.6" rpy="0 0 0" />
      <material name="grey" />
    </visual>
    <collision>
      <geometry>
        <box size="${box_size}" />
      </geometry>
      <origin xyz="0 0 0.6" rpy="0 0 0" />
    </collision>
    <inertial>
      <origin xyz="0 0 0.6" rpy="0 0 0" />
      <mass value="1.0" />
      <inertia ixx="0.1" ixy="0.0" ixz="0.0" iyy="0.1" iyz="0.0" izz="0.1" />
    </inertial>
  </link>

  <gazebo reference="light_fixture_1">
    <material>Gazebo/Grey</material>
    <gravity>0</gravity>
  </gazebo>

  <!-- Traffic Light Model 2 -->
  <link name="light_fixture_2">
    <visual>
      <geometry>
        <box size="${box_size}" />
      </geometry>
      <origin xyz="0 0 2.6" rpy="0 0 0" />
      <material name="grey" />
    </visual>
    <collision>
      <geometry>
        <box size="${box_size}" />
      </geometry>
      <origin xyz="0 0 2.6" rpy="0 0 0" />
    </collision>
    <inertial>
      <origin xyz="0 0 2.6" rpy="0 0 0" />
      <mass value="1.0" />
      <inertia ixx="0.1" ixy="0.0" ixz="0.0" iyy="0.1" iyz="0.0" izz="0.1" />
    </inertial>
  </link>

  <gazebo reference="light_fixture_2">
    <material>Gazebo/Grey</material>
    <gravity>0</gravity>
  </gazebo>

  <!-- Light Fixtures -->
  <joint name="light_mount_1" type="fixed">
    <parent link="cross_beam"/>
    <child link="light_fixture_1"/>
    <origin xyz="0.13 -0.535 6.0" rpy="-1.5707 0 0"/>
  </joint>

  <joint name="light_mount_2" type="fixed">
    <parent link="base"/>
    <child link="light_fixture_2"/>
    <origin xyz="0.3 0 0.1" rpy="0 0 0"/>
  </joint>

  <!-- Traffic Light Components -->
  <link name="green_off_1">
    <visual>
      <geometry>
        <cylinder radius="${cylinder_radius}" length="${green_off_length}" />
      </geometry>
      <origin xyz="0.075 0 0.25" rpy="0 1.5707 0" />
      <material name="black" />
    </visual>
    <collision>
      <geometry>
        <cylinder radius="${cylinder_radius}" length="${green_off_length}" />
      </geometry>
      <origin xyz="0.075 0 0.25" rpy="0 1.5707 0" />
    </collision>
    <inertial>
      <origin xyz="0 0 0" rpy="0 0 0" />
      <mass value="0.1" />
      <inertia ixx="0.1" ixy="0.0" ixz="0.0" iyy="0.1" iyz="0.0" izz="0.1" />
    </inertial>
  </link>

  <gazebo reference="green_off_1">
    <material>Gazebo/Black</material>
    <gravity>0</gravity>
  </gazebo>

  <link name="green_on_1">
    <visual>
      <geometry>
        <cylinder radius="${cylinder_radius}" length="${green_on_length}" />
      </geometry>
      <origin xyz="0 0 0.25" rpy="0 1.5707 0" />
      <material name="green" />
    </visual>
    <collision>
      <geometry>
        <cylinder radius="${cylinder_radius}" length="${green_on_length}" />
      </geometry>
      <origin xyz="0 0 0.25" rpy="0 1.5707 0" />
    </collision>
    <inertial>
      <origin xyz="0 0 0" rpy="0 0 0" />
      <mass value="0.1" />
      <inertia ixx="0.1" ixy="0.0" ixz="0.0" iyy="0.1" iyz="0.0" izz="0.1" />
    </inertial>
  </link>

  <gazebo reference="green_on_1">
    <material>Gazebo/Green</material>
    <gravity>0</gravity>
  </gazebo>

  <link name="yellow_off_1">
    <visual>
      <geometry>
        <cylinder radius="${cylinder_radius}" length="${yellow_off_length}" />
      </geometry>
      <origin xyz="0.075 0 0.6" rpy="0 1.5707 0" />
      <material name="black" />
    </visual>
    <collision>
      <geometry>
        <cylinder radius="${cylinder_radius}" length="${yellow_off_length}" />
      </geometry>
      <origin xyz="0.075 0 0.6" rpy="0 1.5707 0" />
    </collision>
    <inertial>
      <origin xyz="0 0 0" rpy="0 0 0" />
      <mass value="0.1" />
      <inertia ixx="0.1" ixy="0.0" ixz="0.0" iyy="0.1" iyz="0.0" izz="0.1" />
    </inertial>
  </link>

  <gazebo reference="yellow_off_1">
    <material>Gazebo/Black</material>
    <gravity>0</gravity>
  </gazebo>

  <link name="yellow_on_1">
    <visual>
      <geometry>
        <cylinder radius="${cylinder_radius}" length="${yellow_on_length}" />
      </geometry>
      <origin xyz="0 0 0.6" rpy="0 1.5707 0" />
      <material name="yellow" />
    </visual>
    <collision>
      <geometry>
        <cylinder radius="${cylinder_radius}" length="${yellow_on_length}" />
      </geometry>
      <origin xyz="0 0 0.6" rpy="0 1.5707 0" />
    </collision>
    <inertial>
      <origin xyz="0 0 0" rpy="0 0 0" />
      <mass value="0.1" />
      <inertia ixx="0.1" ixy="0.0" ixz="0.0" iyy="0.1" iyz="0.0" izz="0.1" />
    </inertial>
  </link>

  <gazebo reference="yellow_on_1">
    <material>Gazebo/Yellow</material>
    <gravity>0</gravity>
  </gazebo>

  <link name="red_off_1">
    <visual>
      <geometry>
        <cylinder radius="${cylinder_radius}" length="${red_off_length}" />
      </geometry>
      <origin xyz="0.075 0 0.95" rpy="0 1.5707 0" />
      <material name="black" />
    </visual>
    <collision>
      <geometry>
        <cylinder radius="${cylinder_radius}" length="${red_off_length}" />
      </geometry>
      <origin xyz="0.075 0 0.95" rpy="0 1.5707 0" />
    </collision>
    <inertial>
      <origin xyz="0 0 0" rpy="0 0 0" />
      <mass value="0.1" />
      <inertia ixx="0.1" ixy="0.0" ixz="0.0" iyy="0.1" iyz="0.0" izz="0.1" />
    </inertial>
  </link>

  <gazebo reference="red_off_1">
    <material>Gazebo/Black</material>
    <gravity>0</gravity>
  </gazebo>

  <link name="red_on_1">
    <visual>
      <geometry>
        <cylinder radius="${cylinder_radius}" length="${red_on_length}" />
      </geometry>
      <origin xyz="0 0 0.95" rpy="0 1.5707 0" />
      <material name="red" />
    </visual>
    <collision>
      <geometry>
        <cylinder radius="${cylinder_radius}" length="${red_on_length}" />
      </geometry>
      <origin xyz="0 0 0.95" rpy="0 1.5707 0" />
    </collision>
    <inertial>
      <origin xyz="0 0 0" rpy="0 0 0" />
      <mass value="0.1" />
      <inertia ixx="0.1" ixy="0.0" ixz="0.0" iyy="0.1" iyz="0.0" izz="0.1" />
    </inertial>
  </link>

  <gazebo reference="red_on_1">
    <material>Gazebo/Red</material>
    <gravity>0</gravity>
  </gazebo>

  <!-- Traffic Light Components 2 -->
  <link name="green_off_2">
    <visual>
      <geometry>
        <cylinder radius="${cylinder_radius}" length="${green_off_length}" />
      </geometry>
      <origin xyz="0.075 0 2.25" rpy="0 1.5707 0" />
      <material name="black" />
    </visual>
    <collision>
      <geometry>
        <cylinder radius="${cylinder_radius}" length="${green_off_length}" />
      </geometry>
      <origin xyz="0.075 0 2.25" rpy="0 1.5707 0" />
    </collision>
    <inertial>
      <origin xyz="0 0 0" rpy="0 0 0" />
      <mass value="0.1" />
      <inertia ixx="0.1" ixy="0.0" ixz="0.0" iyy="0.1" iyz="0.0" izz="0.1" />
    </inertial>
  </link>

  <gazebo reference="green_off_2">
    <material>Gazebo/Black</material>
    <gravity>0</gravity>
  </gazebo>

  <link name="green_on_2">
    <visual>
      <geometry>
        <cylinder radius="${cylinder_radius}" length="${green_on_length}" />
      </geometry>
      <origin xyz="0 0 2.25" rpy="0 1.5707 0" />
      <material name="green" />
    </visual>
    <collision>
      <geometry>
        <cylinder radius="${cylinder_radius}" length="${green_on_length}" />
      </geometry>
      <origin xyz="0 0 2.25" rpy="0 1.5707 0" />
    </collision>
    <inertial>
      <origin xyz="0 0 0" rpy="0 0 0" />
      <mass value="0.1" />
      <inertia ixx="0.1" ixy="0.0" ixz="0.0" iyy="0.1" iyz="0.0" izz="0.1" />
    </inertial>
  </link>

  <gazebo reference="green_on_2">
    <material>Gazebo/Green</material>
    <gravity>0</gravity>
  </gazebo>

  <link name="yellow_off_2">
    <visual>
      <geometry>
        <cylinder radius="${cylinder_radius}" length="${yellow_off_length}" />
      </geometry>
      <origin xyz="0.075 0 2.6" rpy="0 1.5707 0" />
      <material name="black" />
    </visual>
    <collision>
      <geometry>
        <cylinder radius="${cylinder_radius}" length="${yellow_off_length}" />
      </geometry>
      <origin xyz="0.075 0 2.6" rpy="0 1.5707 0" />
    </collision>
    <inertial>
      <origin xyz="0 0 0" rpy="0 0 0" />
      <mass value="0.1" />
      <inertia ixx="0.1" ixy="0.0" ixz="0.0" iyy="0.1" iyz="0.0" izz="0.1" />
    </inertial>
  </link>

  <gazebo reference="yellow_off_2">
    <material>Gazebo/Black</material>
    <gravity>0</gravity>
  </gazebo>

  <link name="yellow_on_2">
    <visual>
      <geometry>
        <cylinder radius="${cylinder_radius}" length="${yellow_on_length}" />
      </geometry>
      <origin xyz="0 0 2.6" rpy="0 1.5707 0" />
      <material name="yellow" />
    </visual>
    <collision>
      <geometry>
        <cylinder radius="${cylinder_radius}" length="${yellow_on_length}" />
      </geometry>
      <origin xyz="0 0 2.6" rpy="0 1.5707 0" />
    </collision>
    <inertial>
      <origin xyz="0 0 0" rpy="0 0 0" />
      <mass value="0.1" />
      <inertia ixx="0.1" ixy="0.0" ixz="0.0" iyy="0.1" iyz="0.0" izz="0.1" />
    </inertial>
  </link>

  <gazebo reference="yellow_on_2">
    <material>Gazebo/Yellow</material>
    <gravity>0</gravity>
  </gazebo>

  <link name="red_off_2">
    <visual>
      <geometry>
        <cylinder radius="${cylinder_radius}" length="${red_off_length}" />
      </geometry>
      <origin xyz="0.075 0 2.95" rpy="0 1.5707 0" />
      <material name="black" />
    </visual>
    <collision>
      <geometry>
        <cylinder radius="${cylinder_radius}" length="${red_off_length}" />
      </geometry>
      <origin xyz="0.075 0 2.95" rpy="0 1.5707 0" />
    </collision>
    <inertial>
      <origin xyz="0 0 0" rpy="0 0 0" />
      <mass value="0.1" />
      <inertia ixx="0.1" ixy="0.0" ixz="0.0" iyy="0.1" iyz="0.0" izz="0.1" />
    </inertial>
  </link>

  <gazebo reference="red_off_2">
    <material>Gazebo/Black</material>
    <gravity>0</gravity>
  </gazebo>

  <link name="red_on_2">
    <visual>
      <geometry>
        <cylinder radius="${cylinder_radius}" length="${red_on_length}" />
      </geometry>
      <origin xyz="0 0 2.95" rpy="0 1.5707 0" />
      <material name="red" />
    </visual>
    <collision>
      <geometry>
        <cylinder radius="${cylinder_radius}" length="${red_on_length}" />
      </geometry>
      <origin xyz="0 0 2.95" rpy="0 1.5707 0" />
    </collision>
    <inertial>
      <origin xyz="0 0 0" rpy="0 0 0" />
      <mass value="0.1" />
      <inertia ixx="0.1" ixy="0.0" ixz="0.0" iyy="0.1" iyz="0.0" izz="0.1" />
    </inertial>
  </link>

  <gazebo reference="red_on_2">
    <material>Gazebo/Red</material>
    <gravity>0</gravity>
  </gazebo>

  <joint name="green_switch_1" type="fixed">
    <parent link="light_fixture_1" />
    <child link="green_off_1" />
    <origin xyz="0 0 0" rpy="0 0 0" />
  </joint>

  <joint name="green_base_1" type="prismatic">
    <parent link="light_fixture_1" />
    <child link="green_on_1" />
    <origin xyz="0 0 0" rpy="0 0 0" />
    <axis xyz="1 0 0" />
    <limit lower="0" upper="0.101" effort="100" velocity="100" />
  </joint>

  <joint name="yellow_switch_1" type="fixed">
    <parent link="light_fixture_1" />
    <child link="yellow_off_1" />
    <origin xyz="0 0 0" rpy="0 0 0" />
  </joint>

  <joint name="yellow_base_1" type="prismatic">
    <parent link="light_fixture_1" />
    <child link="yellow_on_1" />
    <origin xyz="0 0 0" rpy="0 0 0" />
    <axis xyz="1 0 0" />
    <limit lower="0" upper="0.101" effort="100" velocity="100" />
  </joint>

  <joint name="red_switch_1" type="fixed">
    <parent link="light_fixture_1" />
    <child link="red_off_1" />
    <origin xyz="0 0 0" rpy="0 0 0" />
  </joint>

  <joint name="red_base_1" type="prismatic">
    <parent link="light_fixture_1" />
    <child link="red_on_1" />
    <origin xyz="0 0 0" rpy="0 0 0" />
    <axis xyz="1 0 0" />
    <limit lower="0" upper="0.101" effort="100" velocity="100" />
  </joint>

  <joint name="green_switch_2" type="fixed">
    <parent link="light_fixture_2" />
    <child link="green_off_2" />
    <origin xyz="0 0 0" rpy="0 0 0" />
  </joint>

  <joint name="green_base_2" type="prismatic">
    <parent link="light_fixture_2" />
    <child link="green_on_2" />
    <origin xyz="0 0 0" rpy="0 0 0" />
    <axis xyz="1 0 0" />
    <limit lower="0" upper="0.101" effort="100" velocity="100" />
  </joint>

  <joint name="yellow_switch_2" type="fixed">
    <parent link="light_fixture_2" />
    <child link="yellow_off_2" />
    <origin xyz="0 0 0" rpy="0 0 0" />
  </joint>

  <joint name="yellow_base_2" type="prismatic">
    <parent link="light_fixture_2" />
    <child link="yellow_on_2" />
    <origin xyz="0 0 0" rpy="0 0 0" />
    <axis xyz="1 0 0" />
    <limit lower="0" upper="0.101" effort="100" velocity="100" />
  </joint>

  <joint name="red_switch_2" type="fixed">
    <parent link="light_fixture_2" />
    <child link="red_off_2" />
    <origin xyz="0 0 0" rpy="0 0 0" />
  </joint>

  <joint name="red_base_2" type="prismatic">
    <parent link="light_fixture_2" />
    <child link="red_on_2" />
    <origin xyz="0 0 0" rpy="0 0 0" />
    <axis xyz="1 0 0" />
    <limit lower="0" upper="0.101" effort="100" velocity="100" />
  </joint>

</robot>